Traceback (most recent call last):
  File "C:\Users\D\Anaconda3\lib\site-packages\websockets\protocol.py", line 530, in transfer_data
    msg = yield from self.read_message()
  File "C:\Users\D\Anaconda3\lib\site-packages\websockets\protocol.py", line 582, in read_message
    frame = yield from self.read_data_frame(max_size=self.max_size)
  File "C:\Users\D\Anaconda3\lib\site-packages\websockets\protocol.py", line 647, in read_data_frame
    frame = yield from self.read_frame(max_size)
  File "C:\Users\D\Anaconda3\lib\site-packages\websockets\protocol.py", line 712, in read_frame
    extensions=self.extensions,
  File "C:\Users\D\Anaconda3\lib\site-packages\websockets\framing.py", line 100, in read
    data = yield from reader(2)
  File "C:\Users\D\Anaconda3\lib\asyncio\streams.py", line 668, in readexactly
    yield from self._wait_for_data('readexactly')
  File "C:\Users\D\Anaconda3\lib\asyncio\streams.py", line 458, in _wait_for_data
    yield from self._waiter
  File "C:\Users\D\Anaconda3\lib\asyncio\selector_events.py", line 724, in _read_ready
    data = self._sock.recv(self.max_size)
ConnectionResetError: [WinError 10054] Eine vorhandene Verbindung wurde vom Remotehost geschlossen

The above exception was the direct cause of the following exception:

Traceback (most recent call last):
  File "C:\Users\D\Anaconda3\lib\site-packages\sc2\protocol.py", line 34, in __request
    response_bytes = await self._ws.recv()
  File "C:\Users\D\Anaconda3\lib\site-packages\websockets\protocol.py", line 352, in recv
    yield from self.ensure_open()
  File "C:\Users\D\Anaconda3\lib\site-packages\websockets\protocol.py", line 503, in ensure_open
    self.close_code, self.close_reason) from self.transfer_data_exc
websockets.exceptions.ConnectionClosed: WebSocket connection is closed: code = 1006 (connection closed abnormally [internal]), no reason

During handling of the above exception, another exception occurred:

Traceback (most recent call last):
  File "C:\Ladder\Bots\cannon-lover\__init__.py", line 74, in join_ladder_game
    result = await sc2.main._play_game(players[0], client, realtime, portconfig, step_time_limit, game_time_limit)
  File "C:\Users\D\Anaconda3\lib\site-packages\sc2\main.py", line 84, in _play_game
    result = await _play_game_ai(client, player_id, player.ai, realtime, step_time_limit, game_time_limit)
  File "C:\Users\D\Anaconda3\lib\site-packages\sc2\main.py", line 71, in _play_game_ai
    await client.step()
  File "C:\Users\D\Anaconda3\lib\site-packages\sc2\client.py", line 98, in step
    result = await self._execute(step=sc_pb.RequestStep(count=8))
  File "C:\Users\D\Anaconda3\lib\site-packages\sc2\protocol.py", line 47, in _execute
    response = await self.__request(request)
  File "C:\Users\D\Anaconda3\lib\site-packages\sc2\protocol.py", line 37, in __request
    raise ConnectionAlreadyClosed("Connection already closed.")
sc2.protocol.ConnectionAlreadyClosed: Connection already closed.

During handling of the above exception, another exception occurred:

Traceback (most recent call last):
  File "run.py", line 16, in <module>
    run_ladder_game(bot)
  File "C:\Ladder\Bots\cannon-lover\__init__.py", line 64, in run_ladder_game
    result = asyncio.get_event_loop().run_until_complete(g)
  File "C:\Users\D\Anaconda3\lib\asyncio\base_events.py", line 467, in run_until_complete
    return future.result()
  File "C:\Ladder\Bots\cannon-lover\__init__.py", line 79, in join_ladder_game
    except ConnectionAlreadyClosed:
NameError: name 'ConnectionAlreadyClosed' is not defined
Traceback (most recent call last):
  File "C:\Users\D\Anaconda3\lib\site-packages\websockets\protocol.py", line 530, in transfer_data
    msg = yield from self.read_message()
  File "C:\Users\D\Anaconda3\lib\site-packages\websockets\protocol.py", line 582, in read_message
    frame = yield from self.read_data_frame(max_size=self.max_size)
  File "C:\Users\D\Anaconda3\lib\site-packages\websockets\protocol.py", line 647, in read_data_frame
    frame = yield from self.read_frame(max_size)
  File "C:\Users\D\Anaconda3\lib\site-packages\websockets\protocol.py", line 712, in read_frame
    extensions=self.extensions,
  File "C:\Users\D\Anaconda3\lib\site-packages\websockets\framing.py", line 100, in read
    data = yield from reader(2)
  File "C:\Users\D\Anaconda3\lib\asyncio\streams.py", line 668, in readexactly
    yield from self._wait_for_data('readexactly')
  File "C:\Users\D\Anaconda3\lib\asyncio\streams.py", line 458, in _wait_for_data
    yield from self._waiter
  File "C:\Users\D\Anaconda3\lib\asyncio\selector_events.py", line 724, in _read_ready
    data = self._sock.recv(self.max_size)
ConnectionResetError: [WinError 10054] Eine vorhandene Verbindung wurde vom Remotehost geschlossen

The above exception was the direct cause of the following exception:

Traceback (most recent call last):
  File "C:\Users\D\Anaconda3\lib\site-packages\sc2\protocol.py", line 34, in __request
    response_bytes = await self._ws.recv()
  File "C:\Users\D\Anaconda3\lib\site-packages\websockets\protocol.py", line 352, in recv
    yield from self.ensure_open()
  File "C:\Users\D\Anaconda3\lib\site-packages\websockets\protocol.py", line 503, in ensure_open
    self.close_code, self.close_reason) from self.transfer_data_exc
websockets.exceptions.ConnectionClosed: WebSocket connection is closed: code = 1006 (connection closed abnormally [internal]), no reason

During handling of the above exception, another exception occurred:

Traceback (most recent call last):
  File "C:\Ladder\Bots\cannon-lover\__init__.py", line 78, in join_ladder_game
    await client.quit()
  File "C:\Users\D\Anaconda3\lib\site-packages\sc2\protocol.py", line 66, in quit
    await self._execute(quit=sc_pb.RequestQuit())
  File "C:\Users\D\Anaconda3\lib\site-packages\sc2\protocol.py", line 47, in _execute
    response = await self.__request(request)
  File "C:\Users\D\Anaconda3\lib\site-packages\sc2\protocol.py", line 37, in __request
    raise ConnectionAlreadyClosed("Connection already closed.")
sc2.protocol.ConnectionAlreadyClosed: Connection already closed.

During handling of the above exception, another exception occurred:

Traceback (most recent call last):
  File "run.py", line 16, in <module>
    run_ladder_game(bot)
  File "C:\Ladder\Bots\cannon-lover\__init__.py", line 64, in run_ladder_game
    result = asyncio.get_event_loop().run_until_complete(g)
  File "C:\Users\D\Anaconda3\lib\asyncio\base_events.py", line 467, in run_until_complete
    return future.result()
  File "C:\Ladder\Bots\cannon-lover\__init__.py", line 79, in join_ladder_game
    except ConnectionAlreadyClosed:
NameError: name 'ConnectionAlreadyClosed' is not defined
